Workbook

Sheet Sheet1
B3: Column Labels
B4: Beauty | C4: Electronics | D4: Fashion | E4: Home | F4: Sports | G4: Grand Total
A5: Sum of Revenue | B5: 127646.15 | C5: 163629.25 | D5: 136503.85 | E5: 126172 | F5: 147431.3 | G5: 701382.55

Sheet Sheet2
A3: Row Labels | B3: Count of Order_ID
A4: no | B4: 170
A5: yes | B5: 330
A6: (blank)
A7: Grand Total | B7: 500

Sheet Sheet3
A3: Row Labels | B3: Count of Revenue
A4: Jan | B4: 25
A5: Feb | B5: 40
A6: Mar | B6: 20
A7: Apr | B7: 45
A8: May | B8: 37
A9: Jun | B9: 38
A10: Jul | B10: 29
A11: Aug | B11: 41
A12: Sep | B12: 35
A13: Oct | B13: 36
A14: Nov | B14: 32
A15: Dec | B15: 32
A16: Grand Total | B16: 410

Sheet raw data
A1: Order_ID | B1: Order_Date | C1: Customer_ID | D1: Category | E1: Product | F1: Quantity | G1: Price | H1: Discount | I1: Revenue | J1: high value order | K1: Discounted orders | L1: Repeated customer | M1: High discount orders | N1: Vip customers | O1: customer total revenue | P1: outliner flag
A2: O10000 | B2: 45029 | C2: C101 | D2: Home | E2: P59 | F2: 2 | G2: 199 | H2: 10 | I2: 358.2 | J2: =IF(I2>formulas!$B$5,"yes","no") -> no | K2: =IF(H2>0,"yes","no") -> yes | L2: =IF(COUNTIF('raw data'!$B$2:$B$501,B2)>1,"Yes","No") -> Yes | M2: =IF(H2>15,"yes","no") -> no | N2: =IF(AND(L2="Yes", J2="yes" ),"Yes","No") -> No | O2: =SUMIF('raw data'!B$2:B$501,B2,'raw data'!I$2:I$501) -> 3914.8 | P2: =IF(OR(I2<Visualization!$B$6,I2>Visualization!$B$7),"Outlier","Normal") -> Outlier
A3: O10001 | B3: 45275 | C3: C191 | D3: Beauty | E3: P37 | F3: 2 | G3: 199 | H3: 15 | I3: 358.2 | J3: =IF(I3>formulas!$B$5,"yes","no") -> no | K3: =IF(H3>0,"yes","no") -> yes | L3: =IF(COUNTIF('raw data'!$B$2:$B$501,B3)>1,"Yes","No") -> Yes | M3: =IF(H3>15,"yes","no") -> no | N3: =IF(AND(L3="Yes", J3="yes" ),"Yes","No") -> No | O3: =SUMIF('raw data'!B$2:B$501,B3,'raw data'!I$2:I$501) -> 7282.8 | P3: =IF(OR(I3<Visualization!$B$6,I3>Visualization!$B$7),"Outlier","Normal") -> Outlier
A4: O10002 | B4: 45197 | C4: C131 | D4: Electronics | E4: P61 | F4: 2 | G4: 299 | H4: 5 | I4: 358.2 | J4: =IF(I4>formulas!$B$5,"yes","no") -> no | K4: =IF(H4>0,"yes","no") -> yes | L4: =IF(COUNTIF('raw data'!$B$2:$B$501,B4)>1,"Yes","No") -> Yes | M4: =IF(H4>15,"yes","no") -> no | N4: =IF(AND(L4="Yes", J4="yes" ),"Yes","No") -> No | O4: =SUMIF('raw data'!B$2:B$501,B4,'raw data'!I$2:I$501) -> 3556.6 | P4: =IF(OR(I4<Visualization!$B$6,I4>Visualization!$B$7),"Outlier","Normal") -> Outlier
A5: O10003 | B5: 45033 | C5: C190 | D5: Home | E5: P43 | F5: 3 | H5: 0 | I5: 358.2 | J5: =IF(I5>formulas!$B$5,"yes","no") -> no | K5: =IF(H5>0,"yes","no") -> no | L5: =IF(COUNTIF('raw data'!$B$2:$B$501,B5)>1,"Yes","No") -> No | M5: =IF(H5>15,"yes","no") -> no | N5: =IF(AND(L5="Yes", J5="yes" ),"Yes","No") -> No | O5: =SUMIF('raw data'!B$2:B$501,B5,'raw data'!I$2:I$501) -> 358.2 | P5: =IF(OR(I5<Visualization!$B$6,I5>Visualization!$B$7),"Outlier","Normal") -> Outlier | AA5: q1 = quartile.inc(i2:i501,1)
A6: O10004 | B6: 44998 | C6: C183 | D6: Electronics | E6: P70 | F6: 1 | G6: 199 | I6: 358.2 | J6: =IF(I6>formulas!$B$5,"yes","no") -> no | K6: =IF(H6>0,"yes","no") -> no | L6: =IF(COUNTIF('raw data'!$B$2:$B$501,B6)>1,"Yes","No") -> No | M6: =IF(H6>15,"yes","no") -> no | N6: =IF(AND(L6="Yes", J6="yes" ),"Yes","No") -> No | O6: =SUMIF('raw data'!B$2:B$501,B6,'raw data'!I$2:I$501) -> 358.2 | P6: =IF(OR(I6<Visualization!$B$6,I6>Visualization!$B$7),"Outlier","Normal") -> Outlier | U6: =COUNTIF(P2:P501,"outlier") -> 393
A7: O10005 | B7: 45115 | C7: C123 | D7: Fashion | E7: P39 | F7: 2 | G7: 999 | H7: 20 | I7: 358.2 | J7: =IF(I7>formulas!$B$5,"yes","no") -> no | K7: =IF(H7>0,"yes","no") -> yes | L7: =IF(COUNTIF('raw data'!$B$2:$B$501,B7)>1,"Yes","No") -> Yes | M7: =IF(H7>15,"yes","no") -> yes | N7: =IF(AND(L7="Yes", J7="yes" ),"Yes","No") -> No | O7: =SUMIF('raw data'!B$2:B$501,B7,'raw data'!I$2:I$501) -> 756.2 | P7: =IF(OR(I7<Visualization!$B$6,I7>Visualization!$B$7),"Outlier","Normal") -> Outlier
A8: O10006 | B8: 44947 | C8: C111 | D8: Home | E8: P56 | F8: 3 | G8: 1499 | H8: 10 | I8: 358.2 | J8: =IF(I8>formulas!$B$5,"yes","no") -> no | K8: =IF(H8>0,"yes","no") -> yes | L8: =IF(COUNTIF('raw data'!$B$2:$B$501,B8)>1,"Yes","No") -> Yes | M8: =IF(H8>15,"yes","no") -> no | N8: =IF(AND(L8="Yes", J8="yes" ),"Yes","No") -> No | O8: =SUMIF('raw data'!B$2:B$501,B8,'raw data'!I$2:I$501) -> 1782.25 | P8: =IF(OR(I8<Visualization!$B$6,I8>Visualization!$B$7),"Outlier","Normal") -> Outlier
A9: O10007 | B9: 45029 | C9: C149 | D9: Fashion | E9: P63 | F9: 5 | G9: 1999 | H9: 0 | I9: 358.2 | J9: =IF(I9>formulas!$B$5,"yes","no") -> no | K9: =IF(H9>0,"yes","no") -> no | L9: =IF(COUNTIF('raw data'!$B$2:$B$501,B9)>1,"Yes","No") -> Yes | M9: =IF(H9>15,"yes","no") -> no | N9: =IF(AND(L9="Yes", J9="yes" ),"Yes","No") -> No | O9: =SUMIF('raw data'!B$2:B$501,B9,'raw data'!I$2:I$501) -> 3914.8 | P9: =IF(OR(I9<Visualization!$B$6,I9>Visualization!$B$7),"Outlier","Normal") -> Outlier
A10: O10008 | B10: 45048 | C10: C134 | D10: Home | E10: P46 | F10: 1 | G10: 299 | H10: 20 | I10: 358.2 | J10: =IF(I10>formulas!$B$5,"yes","no") -> no | K10: =IF(H10>0,"yes","no") -> yes | L10: =IF(COUNTIF('raw data'!$B$2:$B$501,B10)>1,"Yes","No") -> Yes | M10: =IF(H10>15,"yes","no") -> yes | N10: =IF(AND(L10="Yes", J10="yes" ),"Yes","No") -> No | O10: =SUMIF('raw data'!B$2:B$501,B10,'raw data'!I$2:I$501) -> 358.2 | P10: =IF(OR(I10<Visualization!$B$6,I10>Visualization!$B$7),"Outlier","Normal") -> Outlier
A11: O10009 | B11: 45141 | C11: C132 | D11: Sports | E11: P88 | F11: 2 | G11: 299 | H11: 20 | I11: 358.2 | J11: =IF(I11>formulas!$B$5,"yes","no") -> no | K11: =IF(H11>0,"yes","no") -> yes | L11: =IF(COUNTIF('raw data'!$B$2:$B$501,B11)>1,"Yes","No") -> Yes | M11: =IF(H11>15,"yes","no") -> yes | N11: =IF(AND(L11="Yes", J11="yes" ),"Yes","No") -> No | O11: =SUMIF('raw data'!B$2:B$501,B11,'raw data'!I$2:I$501) -> 4252.4 | P11: =IF(OR(I11<Visualization!$B$6,I11>Visualization!$B$7),"Outlier","Normal") -> Outlier
A12: O10010 | B12: 45257 | C12: C132 | D12: Beauty | E12: P11 | F12: 2 | G12: 199 | I12: 358.2 | J12: =IF(I12>formulas!$B$5,"yes","no") -> no | K12: =IF(H12>0,"yes","no") -> no | L12: =IF(COUNTIF('raw data'!$B$2:$B$501,B12)>1,"Yes","No") -> Yes | M12: =IF(H12>15,"yes","no") -> no | N12: =IF(AND(L12="Yes", J12="yes" ),"Yes","No") -> No | O12: =SUMIF('raw data'!B$2:B$501,B12,'raw data'!I$2:I$501) -> 1780.35 | P12: =IF(OR(I12<Visualization!$B$6,I12>Visualization!$B$7),"Outlier","Normal") -> Outlier
A13: O10011 | B13: 45014 | C13: C160 | D13: Sports | E13: P62 | F13: 3 | H13: 15 | I13: 358.2 | J13: =IF(I13>formulas!$B$5,"yes","no") -> no | K13: =IF(H13>0,"yes","no") -> yes | L13: =IF(COUNTIF('raw data'!$B$2:$B$501,B13)>1,"Yes","No") -> No | M13: =IF(H13>15,"yes","no") -> no | N13: =IF(AND(L13="Yes", J13="yes" ),"Yes","No") -> No | O13: =SUMIF('raw data'!B$2:B$501,B13,'raw data'!I$2:I$501) -> 358.2 | P13: =IF(OR(I13<Visualization!$B$6,I13>Visualization!$B$7),"Outlier","Normal") -> Outlier
A14: O10012 | B14: 45026 | C14: C150 | D14: Fashion | E14: P77 | F14: 2 | G14: 999 | I14: 358.2 | J14: =IF(I14>formulas!$B$5,"yes","no") -> no | K14: =IF(H14>0,"yes","no") -> no | L14: =IF(COUNTIF('raw data'!$B$2:$B$501,B14)>1,"Yes","No") -> Yes | M14: =IF(H14>15,"yes","no") -> no | N14: =IF(AND(L14="Yes", J14="yes" ),"Yes","No") -> No | O14: =SUMIF('raw data'!B$2:B$501,B14,'raw data'!I$2:I$501) -> 2024.35 | P14: =IF(OR(I14<Visualization!$B$6,I14>Visualization!$B$7),"Outlier","Normal") -> Outlier
A15: O10013 | B15: 45286 | C15: C142 | D15: Beauty | E15: P98 | F15: 2 | H15: 15 | J15: =IF(I15>formulas!$B$5,"yes","no") -> no | K15: =IF(H15>0,"yes","no") -> yes | L15: =IF(COUNTIF('raw data'!$B$2:$B$501,B15)>1,"Yes","No") -> Yes | M15: =IF(H15>15,"yes","no") -> no | N15: =IF(AND(L15="Yes", J15="yes" ),"Yes","No") -> No | O15: =SUMIF('raw data'!B$2:B$501,B15,'raw data'!I$2:I$501) -> 11794.1 | P15: =IF(OR(I15<Visualization!$B$6,I15>Visualization!$B$7),"Outlier","Normal") -> Normal | T15: 0 | U15: {=FREQUENCY(I2:I501,T15:T22)} -> 17
A16: O10014 | B16: 45078 | C16: C111 | D16: Home | E16: P25 | F16: 4 | G16: 499 | H16: 15 | I16: 1696.6 | J16: =IF(I16>formulas!$B$5,"yes","no") -> yes | K16: =IF(H16>0,"yes","no") -> yes | L16: =IF(COUNTIF('raw data'!$B$2:$B$501,B16)>1,"Yes","No") -> Yes | M16: =IF(H16>15,"yes","no") -> no | N16: =IF(AND(L16="Yes", J16="yes" ),"Yes","No") -> Yes | O16: =SUMIF('raw data'!B$2:B$501,B16,'raw data'!I$2:I$501) -> 5519.05 | P16: =IF(OR(I16<Visualization!$B$6,I16>Visualization!$B$7),"Outlier","Normal") -> Outlier | T16: 500
A17: O10015 | B17: 45057 | C17: C166 | D17: Beauty | E17: P71 | F17: 3 | G17: 499 | H17: 0 | I17: 1497 | J17: =IF(I17>formulas!$B$5,"yes","no") -> yes | K17: =IF(H17>0,"yes","no") -> no | L17: =IF(COUNTIF('raw data'!$B$2:$B$501,B17)>1,"Yes","No") -> Yes | M17: =IF(H17>15,"yes","no") -> no | N17: =IF(AND(L17="Yes", J17="yes" ),"Yes","No") -> Yes | O17: =SUMIF('raw data'!B$2:B$501,B17,'raw data'!I$2:I$501) -> 2495 | P17: =IF(OR(I17<Visualization!$B$6,I17>Visualization!$B$7),"Outlier","Normal") -> Outlier | T17: 1000
A18: O10016 | B18: 45076 | C18: C164 | D18: Electronics | E18: P52 | F18: 2 | G18: 1499 | H18: 0 | I18: 2998 | J18: =IF(I18>formulas!$B$5,"yes","no") -> yes | K18: =IF(H18>0,"yes","no") -> no | L18: =IF(COUNTIF('raw data'!$B$2:$B$501,B18)>1,"Yes","No") -> Yes | M18: =IF(H18>15,"yes","no") -> no | N18: =IF(AND(L18="Yes", J18="yes" ),"Yes","No") -> Yes | O18: =SUMIF('raw data'!B$2:B$501,B18,'raw data'!I$2:I$501) -> 2998 | P18: =IF(OR(I18<Visualization!$B$6,I18>Visualization!$B$7),"Outlier","Normal") -> Outlier | T18: 2000
A19: O10017 | B19: 45235 | C19: C132 | D19: Beauty | E19: P4 | F19: 4 | G19: 199 | H19: 10 | I19: 716.4 | J19: =IF(I19>formulas!$B$5,"yes","no") -> no | K19: =IF(H19>0,"yes","no") -> yes | L19: =IF(COUNTIF('raw data'!$B$2:$B$501,B19)>1,"Yes","No") -> No | M19: =IF(H19>15,"yes","no") -> no | N19: =IF(AND(L19="Yes", J19="yes" ),"Yes","No") -> No | O19: =SUMIF('raw data'!B$2:B$501,B19,'raw data'!I$2:I$501) -> 716.4 | P19: =IF(OR(I19<Visualization!$B$6,I19>Visualization!$B$7),"Outlier","Normal") -> Outlier | T19: 3000
A20: O10018 | B20: 45184 | C20: C139 | D20: Electronics | E20: P59 | F20: 3 | G20: 199 | H20: 15 | I20: 507.45 | J20: =IF(I20>formulas!$B$5,"yes","no") -> no | K20: =IF(H20>0,"yes","no") -> yes | L20: =IF(COUNTIF('raw data'!$B$2:$B$501,B20)>1,"Yes","No") -> No | M20: =IF(H20>15,"yes","no") -> no | N20: =IF(AND(L20="Yes", J20="yes" ),"Yes","No") -> No | O20: =SUMIF('raw data'!B$2:B$501,B20,'raw data'!I$2:I$501) -> 507.45 | P20: =IF(OR(I20<Visualization!$B$6,I20>Visualization!$B$7),"Outlier","Normal") -> Outlier | T20: 5000
A21: O10019 | B21: 45270 | C21: C173 | D21: Beauty | E21: P72 | F21: 2 | G21: 199 | H21: 20 | I21: 318.4 | J21: =IF(I21>formulas!$B$5,"yes","no") -> no | K21: =IF(H21>0,"yes","no") -> yes | L21: =IF(COUNTIF('raw data'!$B$2:$B$501,B21)>1,"Yes","No") -> Yes | M21: =IF(H21>15,"yes","no") -> yes | N21: =IF(AND(L21="Yes", J21="yes" ),"Yes","No") -> No | O21: =SUMIF('raw data'!B$2:B$501,B21,'raw data'!I$2:I$501) -> 4815.4 | P21: =IF(OR(I21<Visualization!$B$6,I21>Visualization!$B$7),"Outlier","Normal") -> Outlier | T21: 8000
A22: O10020 | B22: 45220 | C22: C142 | D22: Electronics | E22: P20 | F22: 0 | G22: 1499 | H22: 5 | I22: 0 | J22: =IF(I22>formulas!$B$5,"yes","no") -> no | K22: =IF(H22>0,"yes","no") -> yes | L22: =IF(COUNTIF('raw data'!$B$2:$B$501,B22)>1,"Yes","No") -> Yes | M22: =IF(H22>15,"yes","no") -> no | N22: =IF(AND(L22="Yes", J22="yes" ),"Yes","No") -> No | O22: =SUMIF('raw data'!B$2:B$501,B22,'raw data'!I$2:I$501) -> 3398.3 | P22: =IF(OR(I22<Visualization!$B$6,I22>Visualization!$B$7),"Outlier","Normal") -> Normal | T22: 12000
A23: O10021 | B23: 45118 | C23: C143 | D23: Fashion | E23: P93 | G23: 499 | H23: 10 | J23: =IF(I23>formulas!$B$5,"yes","no") -> no | K23: =IF(H23>0,"yes","no") -> yes | L23: =IF(COUNTIF('raw data'!$B$2:$B$501,B23)>1,"Yes","No") -> Yes | M23: =IF(H23>15,"yes","no") -> no | N23: =IF(AND(L23="Yes", J23="yes" ),"Yes","No") -> No | O23: =SUMIF('raw data'!B$2:B$501,B23,'raw data'!I$2:I$501) -> 0 | P23: =IF(OR(I23<Visualization!$B$6,I23>Visualization!$B$7),"Outlier","Normal") -> Normal
A24: O10022 | B24: 45203 | C24: C128 | D24: Sports | E24: P63 | F24: 1 | H24: 0 | J24: =IF(I24>formulas!$B$5,"yes","no") -> no | K24: =IF(H24>0,"yes","no") -> no | L24: =IF(COUNTIF('raw data'!$B$2:$B$501,B24)>1,"Yes","No") -> Yes | M24: =IF(H24>15,"yes","no") -> no | N24: =IF(AND(L24="Yes", J24="yes" ),"Yes","No") -> No | O24: =SUMIF('raw data'!B$2:B$501,B24,'raw data'!I$2:I$501) -> 3598.2 | P24: =IF(OR(I24<Visualization!$B$6,I24>Visualization!$B$7),"Outlier","Normal") -> Normal
A25: O10023 | B25: 45087 | C25: C112 | D25: Home | E25: P54 | F25: 1 | G25: 1499 | I25: 1499 | J25: =IF(I25>formulas!$B$5,"yes","no") -> yes | K25: =IF(H25>0,"yes","no") -> no | L25: =IF(COUNTIF('raw data'!$B$2:$B$501,B25)>1,"Yes","No") -> Yes | M25: =IF(H25>15,"yes","no") -> no | N25: =IF(AND(L25="Yes", J25="yes" ),"Yes","No") -> Yes | O25: =SUMIF('raw data'!B$2:B$501,B25,'raw data'!I$2:I$501) -> 9893 | P25: =IF(OR(I25<Visualization!$B$6,I25>Visualization!$B$7),"Outlier","Normal") -> Outlier
A26: O10024 | B26: 45240 | C26: C111 | D26: Beauty | E26: P74 | F26: 1 | G26: 1499 | H26: 10 | I26: 1349.1 | J26: =IF(I26>formulas!$B$5,"yes","no") -> no | K26: =IF(H26>0,"yes","no") -> yes | L26: =IF(COUNTIF('raw data'!$B$2:$B$501,B26)>1,"Yes","No") -> Yes | M26: =IF(H26>15,"yes","no") -> no | N26: =IF(AND(L26="Yes", J26="yes" ),"Yes","No") -> No | O26: =SUMIF('raw data'!B$2:B$501,B26,'raw data'!I$2:I$501) -> 1349.1 | P26: =IF(OR(I26<Visualization!$B$6,I26>Visualization!$B$7),"Outlier","Normal") -> Outlier
A27: O10025 | B27: 44948 | C27: C194 | D27: Sports | E27: P98 | F27: 3 | H27: 10 | J27: =IF(I27>formulas!$B$5,"yes","no") -> no | K27: =IF(H27>0,"yes","no") -> yes | L27: =IF(COUNTIF('raw data'!$B$2:$B$501,B27)>1,"Yes","No") -> Yes | M27: =IF(H27>15,"yes","no") -> no | N27: =IF(AND(L27="Yes", J27="yes" ),"Yes","No") -> No | O27: =SUMIF('raw data'!B$2:B$501,B27,'raw data'!I$2:I$501) -> 1699.15 | P27: =IF(OR(I27<Visualization!$B$6,I27>Visualization!$B$7),"Outlier","Normal") -> Normal
A28: O10026 | B28: 45179 | C28: C145 | D28: Home | E28: P57 | F28: 1 | G28: 199 | H28: 10 | I28: 179.1 | J28: =IF(I28>formulas!$B$5,"yes","no") -> no | K28: =IF(H28>0,"yes","no") -> yes | L28: =IF(COUNTIF('raw data'!$B$2:$B$501,B28)>1,"Yes","No") -> Yes | M28: =IF(H28>15,"yes","no") -> no | N28: =IF(AND(L28="Yes", J28="yes" ),"Yes","No") -> No | O28: =SUMIF('raw data'!B$2:B$501,B28,'raw data'!I$2:I$501) -> 717.3 | P28: =IF(OR(I28<Visualization!$B$6,I28>Visualization!$B$7),"Outlier","Normal") -> Outlier
A29: O10027 | B29: 45162 | C29: C101 | D29: Home | E29: P90 | F29: 1 | G29: 999 | H29: 10 | I29: 899.1 | J29: =IF(I29>formulas!$B$5,"yes","no") -> no | K29: =IF(H29>0,"yes","no") -> yes | L29: =IF(COUNTIF('raw data'!$B$2:$B$501,B29)>1,"Yes","No") -> No | M29: =IF(H29>15,"yes","no") -> no | N29: =IF(AND(L29="Yes", J29="yes" ),"Yes","No") -> No | O29: =SUMIF('raw data'!B$2:B$501,B29,'raw data'!I$2:I$501) -> 899.1 | P29: =IF(OR(I29<Visualization!$B$6,I29>Visualization!$B$7),"Outlier","Normal") -> Outlier
A30: O10028 | B30: 45271 | C30: C134 | D30: Electronics | E30: P41 | F30: 1 | H30: 5 | J30: =IF(I30>formulas!$B$5,"yes","no") -> no | K30: =IF(H30>0,"yes","no") -> yes | L30: =IF(COUNTIF('raw data'!$B$2:$B$501,B30)>1,"Yes","No") -> Yes | M30: =IF(H30>15,"yes","no") -> no | N30: =IF(AND(L30="Yes", J30="yes" ),"Yes","No") -> No | O30: =SUMIF('raw data'!B$2:B$501,B30,'raw data'!I$2:I$501) -> 897 | P30: =IF(OR(I30<Visualization!$B$6,I30>Visualization!$B$7),"Outlier","Normal") -> Normal
A31: O10029 | B31: 44975 | C31: C186 | D31: Fashion | E31: P3 | F31: 1 | G31: 499 | I31: 499 | J31: =IF(I31>formulas!$B$5,"yes","no") -> no | K31: =IF(H31>0,"yes","no") -> no | L31: =IF(COUNTIF('raw data'!$B$2:$B$501,B31)>1,"Yes","No") -> Yes | M31: =IF(H31>15,"yes","no") -> no | N31: =IF(AND(L31="Yes", J31="yes" ),"Yes","No") -> No | O31: =SUMIF('raw data'!B$2:B$501,B31,'raw data'!I$2:I$501) -> 668.15 | P31: =IF(OR(I31<Visualization!$B$6,I31>Visualization!$B$7),"Outlier","Normal") -> Outlier
A32: O10030 | B32: 44985 | C32: C180 | D32: Fashion | E32: P6 | F32: 3 | G32: 299 | I32: 897 | J32: =IF(I32>formulas!$B$5,"yes","no") -> no | K32: =IF(H32>0,"yes","no") -> no | L32: =IF(COUNTIF('raw data'!$B$2:$B$501,B32)>1,"Yes","No") -> No | M32: =IF(H32>15,"yes","no") -> no | N32: =IF(AND(L32="Yes", J32="yes" ),"Yes","No") -> No | O32: =SUMIF('raw data'!B$2:B$501,B32,'raw data'!I$2:I$501) -> 897 | P32: =IF(OR(I32<Visualization!$B$6,I32>Visualization!$B$7),"Outlier","Normal") -> Outlier
A33: O10031 | B33: 45096 | C33: C189 | D33: Sports | E33: P5 | F33: 3 | G33: 299 | I33: 897 | J33: =IF(I33>formulas!$B$5,"yes","no") -> no | K33: =IF(H33>0,"yes","no") -> no | L33: =IF(COUNTIF('raw data'!$B$2:$B$501,B33)>1,"Yes","No") -> Yes | M33: =IF(H33>15,"yes","no") -> no | N33: =IF(AND(L33="Yes", J33="yes" ),"Yes","No") -> No | O33: =SUMIF('raw data'!B$2:B$501,B33,'raw data'!I$2:I$501) -> 5689 | P33: =IF(OR(I33<Visualization!$B$6,I33>Visualization!$B$7),"Outlier","Normal") -> Outlier
A34: O10032 | B34: 45114 | C34: C107 | D34: Fashion | E34: P5 | F34: 2 | G34: 1999 | H34: 15 | I34: 3398.3 | J34: =IF(I34>formulas!$B$5,"yes","no") -> yes | K34: =IF(H34>0,"yes","no") -> yes | L34: =IF(COUNTIF('raw data'!$B$2:$B$501,B34)>1,"Yes","No") -> Yes | M34: =IF(H34>15,"yes","no") -> no | N34: =IF(AND(L34="Yes", J34="yes" ),"Yes","No") -> Yes | O34: =SUMIF('raw data'!B$2:B$501,B34,'raw data'!I$2:I$501) -> 6794.9 | P34: =IF(OR(I34<Visualization!$B$6,I34>Visualization!$B$7),"Outlier","Normal") -> Outlier
A35: O10033 | B35: 45197 | C35: C192 | D35: Beauty | E35: P54 | F35: 2 | G35: 1999 | H35: 20 | I35: 3198.4 | J35: =IF(I35>formulas!$B$5,"yes","no") -> yes | K35: =IF(H35>0,"yes","no") -> yes | L35: =IF(COUNTIF('raw data'!$B$2:$B$501,B35)>1,"Yes","No") -> Yes | M35: =IF(H35>15,"yes","no") -> yes | N35: =IF(AND(L35="Yes", J35="yes" ),"Yes","No") -> Yes | O35: =SUMIF('raw data'!B$2:B$501,B35,'raw data'!I$2:I$501) -> 3556.6 | P35: =IF(OR(I35<Visualization!$B$6,I35>Visualization!$B$7),"Outlier","Normal") -> Outlier
A36: O10034 | B36: 45116 | C36: C125 | D36: Fashion | E36: P47 | F36: 3 | G36: 1499 | I36: 4497 | J36: =IF(I36>formulas!$B$5,"yes","no") -> yes | K36: =IF(H36>0,"yes","no") -> no | L36: =IF(COUNTIF('raw data'!$B$2:$B$501,B36)>1,"Yes","No") -> Yes | M36: =IF(H36>15,"yes","no") -> no | N36: =IF(AND(L36="Yes", J36="yes" ),"Yes","No") -> Yes | O36: =SUMIF('raw data'!B$2:B$501,B36,'raw data'!I$2:I$501) -> 6729 | P36: =IF(OR(I36<Visualization!$B$6,I36>Visualization!$B$7),"Outlier","Normal") -> Outlier
A37: O10035 | B37: 45101 | C37: C173 | D37: Sports | E37: P87 | F37: 0 | G37: 299 | H37: 10 | I37: 0 | J37: =IF(I37>formulas!$B$5,"yes","no") -> no | K37: =IF(H37>0,"yes","no") -> yes | L37: =IF(COUNTIF('raw data'!$B$2:$B$501,B37)>1,"Yes","No") -> No | M37: =IF(H37>15,"yes","no") -> no | N37: =IF(AND(L37="Yes", J37="yes" ),"Yes","No") -> No | O37: =SUMIF('raw data'!B$2:B$501,B37,'raw data'!I$2:I$501) -> 0 | P37: =IF(OR(I37<Visualization!$B$6,I37>Visualization!$B$7),"Outlier","Normal") -> Normal
A38: O10036 | B38: 44977 | C38: C189 | D38: Fashion | E38: P49 | F38: 2 | G38: 999 | H38: 10 | I38: 1798.2 | J38: =IF(I38>formulas!$B$5,"yes","no") -> yes | K38: =IF(H38>0,"yes","no") -> yes | L38: =IF(COUNTIF('raw data'!$B$2:$B$501,B38)>1,"Yes","No") -> Yes | M38: =IF(H38>15,"yes","no") -> no | N38: =IF(AND(L38="Yes", J38="yes" ),"Yes","No") -> Yes | O38: =SUMIF('raw data'!B$2:B$501,B38,'raw data'!I$2:I$501) -> 6245.55 | P38: =IF(OR(I38<Visualization!$B$6,I38>Visualization!$B$7),"Outlier","Normal") -> Outlier
A39: O10037 | B39: 45290 | C39: C133 | D39: Beauty | E39: P9 | G39: 199 | J39: =IF(I39>formulas!$B$5,"yes","no") -> no | K39: =IF(H39>0,"yes","no") -> no | L39: =IF(COUNTIF('raw data'!$B$2:$B$501,B39)>1,"Yes","No") -> No | M39: =IF(H39>15,"yes","no") -> no | N39: =IF(AND(L39="Yes", J39="yes" ),"Yes","No") -> No | O39: =SUMIF('raw data'!B$2:B$501,B39,'raw data'!I$2:I$501) -> 0 | P39: =IF(OR(I39<Visualization!$B$6,I39>Visualization!$B$7),"Outlier","Normal") -> Normal
A40: O10038 | B40: 44981 | C40: C106 | D40: Electronics | E40: P99 | F40: 3 | G40: 499 | I40: 1497 | J40: =IF(I40>formulas!$B$5,"yes","no") -> yes | K40: =IF(H40>0,"yes","no") -> no | L40: =IF(COUNTIF('raw data'!$B$2:$B$501,B40)>1,"Yes","No") -> No | M40: =IF(H40>15,"yes","no") -> no | N40: =IF(AND(L40="Yes", J40="yes" ),"Yes","No") -> No | O40: =SUMIF('raw data'!B$2:B$501,B40,'raw data'!I$2:I$501) -> 1497 | P40: =IF(OR(I40<Visualization!$B$6,I40>Visualization!$B$7),"Outlier","Normal") -> Outlier
...

Sheet formulas
A2: TOTAL REVENUE | B2: =SUM('raw data'!I2:I502,) -> 701382.55
A3: TOTAL ORDERS | B3: {=SUM(1/COUNTIF('raw data'!A2:A501,'raw data'!A2:A501))} -> 500
A4: TOTAL CUSTOMER | B4: {=SUM(1/COUNTIF('raw data'!B2:B501,'raw data'!B2:B501))} -> 267
A5: AVERAGE ORDER VALUE | B5: =B2/B3 -> 1402.7651
A6: AVERAGE ITEM PER ORDER | B6: 2.16
A7: AVERAGE DISCOUNT | B7: =AVERAGE('raw data'!H2:H501) -> 10.383693
A8: REVENUE PER CUSTOMER | B8: =B2/B4 -> 2626.9009
B13: =IF(B5<'raw data'!I3,"yes","no") -> no

Sheet validation
A1: TOTAL REVENUE | B1: Blank revenue rows were ignored by SUM
B3: Only numeric revenue values (408 rows) were aggregated
B5: No error values present in revenue column
B7: Verified all Order_IDs are unique
A10: TOTAL ORDERS | B10: COUNT ignored Order_IDs because they are text
B12: COUNTA used to count non-empty Order_IDs
B14: Verified all Order_IDs are unique
A17: TOTAL CUSTOMER | B17: Identified 267 unique customers
B19: COUNTIF-based uniqueness logic applied
B21: Repeat customers correctly consolidated
A23: AVERAGE ORDER VALUE | B23: Calculated as Total Revenue divided by Total Orders
B25: Uses previously validated KPIs
B27: Represents average spend per order
A29: AVERAGE ITEM PER ORDER | B29: Calculated using total quantity sold
B31: Normalized by unique orders
B33: Indicates basket size behavior
A35: AVERAGE DISCOUNT | B35: Calculated as simple average of discount percentages
B37: Blank values excluded automatically
B39: Indicates pricing & promotion intensity
A41: REVENUE PER CUSTOMER | B41: Calculated using validated Total Revenue and Total Customers
B43: Represents average lifetime spend per customer in dataset
B45: Sensitive to repeat purchase behavior
A49: FLAGS
A50: USING IF
A51: HIGH ORDER VALUE | B51: Used absolute reference to lock AOV threshold
B53: Prevented row-shift errors during drag-down
B55: Ensured consistent comparison logic
A57: DISCOUNTED ORDERS | B57: Flagged orders with any discount applied
B59: Zero-discount orders classified separately
B61: Enables promo vs non-promo analysis
A63: REPEATED CUSTOMERS | B63: Identified customers with multiple orders
B65: COUNTIF-based frequency logic applied
B67: Enables retention and loyalty analysis
A69: HIGH DISCOUNTED ORDERS | B69: Flagged orders where discount > 15%
B71: Threshold is adjustable for business strategy
B73: Supports margin and promotion analysis
A75: VIP CUSTOMERS | B75: Customers with multiple high spend orders → Yes
B77: One-time or low spend customers → No
B79: VIP count < Total Customers

Sheet Visualization
